[3.139s] Traceback (most recent call last):
  File "/usr/lib/python3/dist-packages/colcon_core/executor/__init__.py", line 91, in __call__
    rc = await self.task(*args, **kwargs)
  File "/usr/lib/python3/dist-packages/colcon_core/task/__init__.py", line 93, in __call__
    return await task_method(*args, **kwargs)
  File "/usr/lib/python3/dist-packages/colcon_ros/task/ament_python/build.py", line 102, in build
    return await extension.build(additional_hooks=additional_hooks)
  File "/usr/lib/python3/dist-packages/colcon_core/task/python/build.py", line 96, in build
    available_commands = await self._get_available_commands(
  File "/usr/lib/python3/dist-packages/colcon_core/task/python/build.py", line 194, in _get_available_commands
    output = await check_output(
  File "/usr/lib/python3/dist-packages/colcon_core/subprocess.py", line 129, in check_output
    assert not rc, f'Expected {args} to pass: {stderr_data}'
AssertionError: Expected ['/usr/bin/python3', '-W', 'ignore:setup.py install is deprecated', '-W', 'ignore:easy_install command is deprecated', 'setup.py', '--help-commands'] to pass: Traceback (most recent call last):
  File "/usr/lib/python3/dist-packages/pkg_resources/__init__.py", line 2866, in get_entry_map
    ep_map = self._ep_map
  File "/usr/lib/python3/dist-packages/pkg_resources/__init__.py", line 2828, in __getattr__
    raise AttributeError(attr)
AttributeError: _ep_map. Did you mean: '_dep_map'?

During handling of the above exception, another exception occurred:

Traceback (most recent call last):
  File "/home/bestway/bestway_ws/src/yuntai_control/setup.py", line 5, in <module>
    setup(
  File "/usr/lib/python3/dist-packages/setuptools/__init__.py", line 152, in setup
    _install_setup_requires(attrs)
  File "/usr/lib/python3/dist-packages/setuptools/__init__.py", line 142, in _install_setup_requires
    dist = MinimalDistribution(attrs)
  File "/usr/lib/python3/dist-packages/setuptools/__init__.py", line 134, in __init__
    distutils.core.Distribution.__init__(self, filtered)
  File "/usr/lib/python3/dist-packages/setuptools/dist.py", line 457, in __init__
    for ep in pkg_resources.iter_entry_points('distutils.setup_keywords'):
  File "/usr/lib/python3/dist-packages/pkg_resources/__init__.py", line 646, in <genexpr>
    for entry in dist.get_entry_map(group).values()
  File "/usr/lib/python3/dist-packages/pkg_resources/__init__.py", line 2868, in get_entry_map
    ep_map = self._ep_map = EntryPoint.parse_map(
  File "/usr/lib/python3/dist-packages/pkg_resources/__init__.py", line 2549, in parse_map
    for group, lines in data:
  File "/usr/lib/python3/dist-packages/pkg_resources/__init__.py", line 3205, in split_sections
    for line in yield_lines(s):
  File "/usr/lib/python3/dist-packages/pkg_resources/__init__.py", line 2780, in _get_metadata
    for line in self.get_metadata_lines(name):
  File "/usr/lib/python3/dist-packages/pkg_resources/__init__.py", line 1422, in get_metadata_lines
    return yield_lines(self.get_metadata(name))
  File "/usr/lib/python3/dist-packages/pkg_resources/__init__.py", line 1412, in get_metadata
    value = self._get(path)
  File "/usr/lib/python3/dist-packages/pkg_resources/__init__.py", line 1616, in _get
    with open(path, 'rb') as stream:
FileNotFoundError: [Errno 2] No such file or directory: '/home/bestway/bestway_ws/install/nav2_launch/lib/python3.10/site-packages/nav2_launch-0.0.0-py3.10.egg-info/entry_points.txt'

